Workbook

Sheet Documentation
A1: GlowNest FMCG - Marketing Campaign Analysis
A3: OBJECTIVE
A4: Analyze multi-channel marketing campaign performance (Instagram, Facebook, Google Ads, Email, YouTube) for a fictional FMCG personal care brand to identify the highest-ROI channels, regions, and time periods, and support budget allocation decisions.
A6: SHEET GUIDE
A7: Raw_Data - Original unprocessed export, kept unchanged as an audit trail.
A8: Lookup_Tables - Mapping tables used to standardize inconsistent Channel/Region text
A9: (e.g. 'insta', 'FB', ' Instagram ' all map to 'Instagram').
A10: Cleaned_Data - Every raw row cleaned and enriched via formula (no hardcoded values):
A11: text standardized (TRIM/PROPER), dates parsed from 3 mixed formats,
A12: missing Spend/Revenue imputed with channel averages (AVERAGEIFS),
A13: negative Clicks corrected, duplicates flagged (COUNTIF), and
A14: CTR/CPC/CPA/ROAS/Conversion Rate calculated per row.
... A33: 3. Document approach and insights in the GitHub README.

Sheet Final_Data_PowerBI
A1: Campaign_ID | B1: Campaign_Name | C1: Channel | D1: Start_Date | E1: End_Date | F1: Target_Audience | G1: Region | H1: Spend_INR | I1: Impressions | J1: Clicks | K1: Conversions | L1: Revenue_INR | M1: CTR | N1: CPC | O1: CPA | P1: ROAS | Q1: Conversion_Rate
A2: 1179 | B2: Ayurvedic Range Launch | C2: Email | D2: 45320 | E2: 45341 | F2: Male 35-44 | G2: West | H2: 1459.32 | I2: 47777 | J2: 817 | K2: 52 | L2: 57731.18 | M2: 0.017100278 | N2: 1.7861934 | O2: 28.063846 | P2: 39.560329 | Q2: 0.063647491
A3: 1665 | B3: Ayurvedic Range Launch | C3: Google Ads | D3: 45610 | E3: 45623 | F3: Male 45+ | G3: West | H3: 40790.41 | I3: 1371537 | J3: 33827 | K3: 1556 | L3: 1305729.8 | M3: 0.024663571 | N3: 1.2058536 | O3: 26.214916 | P3: 32.010706 | Q3: 0.045998758
A4: 1798 | B4: Herbal Range Awareness | C4: Email | D4: 45595 | E4: 45604 | F4: Female 25-34 | G4: North | H4: 4460.42 | I4: 177985 | J4: 4765 | K4: 161 | L4: 110861.2 | M4: 0.026771919 | N4: 0.93607975 | O4: 27.704472 | P4: 24.854431 | Q4: 0.033788038
A5: 1396 | B5: Clearance Sale Push | C5: Email | D5: 45540 | E5: 45567 | F5: Female 35-44 | G5: West | H5: 1905.7 | I5: 62150 | J5: 1920 | K5: 35 | L5: 23041.61 | M5: 0.030893001 | N5: 0.99255208 | O5: 54.448571 | P5: 12.09089 | Q5: 0.018229167
A6: 1160 | B6: Ayurvedic Range Launch | C6: Email | D6: 45303 | E6: 45310 | F6: Female 25-34 | G6: Central | H6: 7317.47 | I6: 190881 | J6: 1691 | K6: 124 | L6: 192518.24 | M6: 0.0088589226 | N6: 4.3273034 | O6: 59.011855 | P6: 26.309399 | Q6: 0.073329391
A7: 1429 | B7: Baby Care Trust Campaign | C7: YouTube | D7: 45388 | E7: 45408 | F7: Female 45+ | G7: South | H7: 39663.1 | I7: 1548782 | J7: 37434 | K7: 1172 | L7: 701517.37 | M7: 0.024169961 | N7: 1.0595475 | O7: 33.842235 | P7: 17.686902 | Q7: 0.031308436
A8: 1077 | B8: Festive Gift Bundle | C8: Facebook | D8: 45556 | E8: 45564 | F8: Female 25-34 | G8: West | H8: 9690.51 | I8: 184195 | J8: 3403 | K8: 156 | L8: 242582.77 | M8: 0.018474986 | N8: 2.8476374 | O8: 62.118654 | P8: 25.033024 | Q8: 0.045841904
A9: 1595 | B9: Anti-Ageing Serum Push | C9: Email | D9: 45487 | E9: 45492 | F9: Male 18-24 | G9: Central | H9: 6092.9 | I9: 236321 | J9: 6588 | K9: 395 | L9: 397287.84 | M9: 0.027877336 | N9: 0.92484821 | O9: 15.425063 | P9: 65.205048 | Q9: 0.059957498
A10: 1784 | B10: Monsoon Skincare Push | C10: Email | D10: 45362 | E10: 45369 | F10: Male 25-34 | G10: Central | H10: 5243.17 | I10: 112725 | J10: 2739 | K10: 161 | L10: 78789.26 | M10: 0.024298071 | N10: 1.9142643 | O10: 32.566273 | P10: 15.027028 | Q10: 0.058780577
A11: 1326 | B11: Hair Care Revamp | C11: Google Ads | D11: 45555 | E11: 45581 | F11: Female 18-24 | G11: North | H11: 72158.45 | I11: 1282556 | J11: 20479 | K11: 1092 | L11: 961045.35 | M11: 0.015967334 | N11: 3.5235339 | O11: 66.079167 | P11: 13.318542 | Q11: 0.053322916
A12: 1457 | B12: Influencer Collab - Skincare | C12: Google Ads | D12: 45338 | E12: 45368 | F12: Male 45+ | G12: West | H12: 33296.08 | I12: 685737 | J12: 15277 | K12: 1140 | L12: 505894.6 | M12: 0.02227822 | N12: 2.1794907 | O12: 29.207088 | P12: 15.193819 | Q12: 0.074621981
A13: 1084 | B13: Monsoon Skincare Push | C13: Instagram | D13: 45332 | E13: 45347 | F13: Female 25-34 | G13: South | H13: 23373.28 | I13: 611162 | J13: 16214 | K13: 351 | L13: 348777.17 | M13: 0.026529791 | N13: 1.4415493 | O13: 66.590541 | P13: 14.922046 | Q13: 0.021647959
... A821: 1085 | B821: Men'S Grooming Drive | C821: YouTube | D821: 45478 | E821: 45499 | F821: Female 45+ | G821: North | H821: 65955.8 | I821: 2560386 | J821: 23769 | K821: 1248 | L821: 1074726.4 | M821: 0.0092833659 | N821: 2.7748664 | O821: 52.849199 | P821: 16.294646 | Q821: 0.052505364

Sheet Raw_Data
A1: Campaign_ID | B1: Campaign_Name | C1: Channel | D1: Start_Date | E1: End_Date | F1: Target_Audience | G1: Region | H1: Spend_INR | I1: Impressions | J1: Clicks | K1: Conversions | L1: Revenue_INR
A2: 1179 | B2: Ayurvedic Range Launch | C2: e-mail | D2: 29/01/2024 | E2: 19/02/2024 | F2: Male 35-44 | G2: West | H2: 1459.32 | I2: 47777 | J2: 817 | K2: 52 | L2: 57731.18
A3: 1665 | B3: Ayurvedic Range Launch | C3: google ads | D3: 14-Nov-2024 | E3: 27-Nov-2024 | F3: Male 45+ | G3: West | H3: 40790.41 | I3: 1371537 | J3: 33827 | K3: 1556 | L3: 1305729.8
A4: 1798 | B4: HERBAL RANGE AWARENESS | C4: Email | D4: 2024-10-30 | E4: 2024-11-08 | F4: Female 25-34 | G4: Nort | H4: 4460.42 | I4: 177985 | J4: 4765 | K4: 161
A5: 1396 | B5: Clearance Sale Push | C5: Email | D5: 2024-09-05 | E5: 2024-10-02 | F5: Female 35-44 | G5: west | H5: 1905.7 | I5: 62150 | J5: 1920 | K5: 35 | L5: 23041.61
A6: 1160 | B6: Ayurvedic Range Launch | C6: EMAIL | D6: 12/01/2024 | E6: 19/01/2024 | F6: Female 25-34 | G6: Centrl | H6: 7317.47 | I6: 190881 | J6: 1691 | K6: 124 | L6: 192518.24
A7: 1429 | B7: Baby Care Trust Campaign | C7: Youtube | D7: 06/04/2024 | E7: 26/04/2024 | F7: Female 45+ | G7: South | H7: 39663.1 | I7: 1548782 | J7: 37434 | K7: 1172 | L7: 701517.37
A8: 1077 | B8: FESTIVE GIFT BUNDLE | C8: FB | D8: 2024-09-21 | E8: 2024-09-29 | F8: Female 25-34 | G8: WEST | H8: 9690.51 | I8: 184195 | J8: 3403 | K8: 156 | L8: 242582.77
A9: 1595 | B9: Anti-Ageing Serum Push | C9: EMAIL | D9: 2024-07-14 | E9: 2024-07-19 | F9: Male 18-24 | G9: CENTRAL | H9: 6092.9 | I9: 236321 | J9: 6588 | K9: 395 | L9: 397287.84
A10: 1784 | B10: Monsoon Skincare Push | C10: Email | D10: 2024-03-11 | E10: 2024-03-18 | F10: Male 25-34 | G10: Central | H10: 5243.17 | I10: 112725 | J10: 2739 | K10: 161 | L10: 78789.26
A11: 1326 | B11: Hair Care Revamp | C11: GoogleAds | D11: 2024-09-20 | E11: 2024-10-16 | F11: Female 18-24 | G11: Nort | H11: 72158.45 | I11: 1282556 | J11: 20479 | K11: 1092 | L11: 961045.35
A12: 1457 | B12: Influencer Collab - Skincare | C12: Google Ads | D12: 16-Feb-2024 | E12: 17-Mar-2024 | F12: Male 45+ | G12: West | H12: 33296.08 | I12: 685737 | J12: 15277 | K12: 1140 | L12: 505894.6
A13: 1084 | B13: Monsoon Skincare Push | C13: Instagram | D13: 10-Feb-2024 | E13: 25-Feb-2024 | F13: Female 25-34 | G13: South | H13: 23373.28 | I13: 611162 | J13: 16214 | K13: 351 | L13: 348777.17
A14: 1404 | B14: Influencer Collab - Skincare | C14: instagram | D14: 21/11/2024 | E14: 12/12/2024 | F14: Female 25-34 | G14: East | H14: 48709.84 | I14: 904014 | J14: 19177 | K14: 417 | L14: 294186.89
A15: 1345 | B15: Wedding Season Special | C15: instagram | D15: 2024-04-02 | E15: 2024-04-18 | F15: Female 25-34 | G15: East | H15: 30052.78 | I15: 837158 | J15: 14422 | K15: 912 | L15: 734804.23
A16: 1741 | B16: Herbal Range Awareness | C16: google ads | D16: 22-Jan-2024 | E16: 06-Feb-2024 | F16: Female 35-44 | G16: Wst | H16: 74280.91 | I16: 2939136 | J16: 27485 | K16: 932 | L16: 1181227.3
... A23: 1272 | B23: WEDDING SEASON SPECIAL | C23: FB | D23: 2024-01-16 | E23: 2024-02-14 | F23: Female 35-44 | G23: Central | H23: 44725.8 | I23: 1133843 | J23: 19658 | K23: 806 | L23: 1373395.3
A24: 1205 | B24: Wedding Season Special | C24: YOUTUBE | D24: 28/01/2024 | E24: 23/02/2024 | F24: Female 35-44 | H24: 29992.68 | I24: 1012391 | J24: 9949 | K24: 299 | L24: 213280.72
A25: 1806 | B25: Anti-Ageing Serum Push | C25: Instagram | D25: 2024-07-07 | E25: 2024-07-22 | F25: Female 25-34 | G25: south | H25: 27693.68 | I25: 774637 | J25: 10265 | K25: 579 | L25: 922779.24
A26: 1241 | B26: SUNSCREEN SEASON CAMPAIGN | C26: FACEBOOK | D26: 2024-06-25 | E26: 2024-06-30 | F26: Male 25-34 | G26: EAST | H26: 11334.45 | I26: 415795 | J26: 14092 | K26: 337 | L26: 399360.83
A27: 1278 | B27: Monsoon Skincare Push | C27: Facebook | D27: 18/09/2024 | E27: 12/10/2024 | F27: Female 45+ | G27: East | H27: 22661.86 | I27: 555559 | J27: 15582 | K27: 1150 | L27: 1345457.2
A28: 1250 | B28: MEN'S GROOMING DRIVE | C28: Facebook | D28: 14/07/2024 | E28: 19/07/2024 | F28: Male 25-34 | G28: west | H28: 48882.33 | I28: 1606618 | J28: 26579 | K28: 2079 | L28: 1472732.8
A29: 1547 | B29: Baby Care Trust Campaign | C29: Facebook | D29: 2024-11-22 | E29: 2024-12-09 | F29: Male 18-24 | G29: North | H29: 23561 | I29: 885989 | J29: 28166 | K29: 2095 | L29: 2546904.6
A30: 1339 | B30: Herbal Range Awareness | C30: instagram | D30: 2024-08-02 | E30: 2024-08-27 | F30: Male 35-44 | G30: east | H30: 10533.17 | I30: 234801 | J30: 5674 | K30: 87 | L30: 54899.74
A31: 1717 | B31: Ayurvedic Range Launch | C31: YouTube | D31: 09-Sep-2024 | E31: 25-Sep-2024 | F31: Female 25-34 | G31: east | H31: 19530.3 | I31: 661906 | J31: 11849 | K31: 677 | L31: 1119099.6
A32: 1238 | B32: Summer Glow Launch | C32: e-mail | D32: 10/06/2024 | E32: 07/07/2024 | F32: Male 45+ | G32: South | H32: 1082.74 | I32: 21945 | J32: 492 | K32: 16 | L32: 19816.45
A33: 1645 | B33: Sunscreen Season Campaign | C33: instagram | D33: 2024-02-03 | E33: 2024-03-03 | F33: Female 35-44 | G33: Central | H33: 42994.76 | I33: 746569 | J33: 23039 | K33: 782 | L33: 1052642.7
A34: 1169 | B34: Men's Grooming Drive | C34: INSTAGRAM | D34: 2024-03-26 | E34: 2024-04-13 | F34: Female 45+ | G34: North | H34: 53852.07 | I34: 1280644 | J34: 20823 | K34: 1416 | L34: 2115020.4
A35: 1653 | B35: Baby Care Trust Campaign | C35: Instagram | D35: 20-Oct-2024 | E35: 08-Nov-2024 | F35: Female 25-34 | G35: Nort | H35: 41809.05 | I35: 826656 | J35: 5945 | K35: 344 | L35: 528296.58
A36: 1233 | B36: Hair Care Revamp | C36: youtube | D36: 26/06/2024 | E36: 09/07/2024 | F36: Male 35-44 | G36: Nort | H36: 60477.26 | I36: 1201267 | J36: 39511 | K36: 1985 | L36: 1446282.7
A37: 1525 | B37: Ayurvedic Range Launch | C37: instagram | D37: 04-Sep-2024 | E37: 28-Sep-2024 | F37: Male 35-44 | G37: North | H37: 36417.1 | I37: 690457 | J37: 18815 | K37: 1408
A38: 1231 | B38: Sunscreen Season Campaign | C38: instagram | D38: 07-Nov-2024 | E38: 13-Nov-2024 | F38: Female 25-34 | G38: NORTH | H38: 27984.95 | I38: 1108517 | J38: 25960 | K38: 1206 | L38: 1666485.1
A39: 1047 | B39: Herbal Range Awareness | C39: Email | D39: 10/09/2024 | E39: 16/09/2024 | F39: Female 35-44 | G39: West | H39: 4516.04 | I39: 134372 | J39: 4177 | K39: 297 | L39: 293567.87
A40: 1497 | B40: Baby Care Trust Campaign | C40: Instagram | D40: 2024-04-03 | E40: 2024-05-02 | F40: Female 35-44 | G40: South | H40: 26335.66 | I40: 720416 | J40: 14003 | K40: 1093 | L40: 1336222.6
A41: 1082 | B41: Clearance Sale Push | C41: Facebook | D41: 19/01/2024 | E41: 02/02/2024 | F41: Male 45+ | G41: South | H41: 7927.48 | I41: 158444 | J41: 991 | K41: 74 | L41: 81200.66
A42: 1536 | B42: Back to College Offer | C42: google ads | D42: 15/09/2024 | E42: 23/09/2024 | F42: Female 35-44 | G42: EAST | H42: 25314.94 | I42: 609864 | J42: 20889 | K42: 1477 | L42: 1616610.3
A43: 1365 | B43: Back to College Offer | C43: youtube | D43: 13-May-2024 | E43: 23-May-2024 | F43: Female 35-44 | G43: East | H43: 59476.53 | I43: 1379231 | J43: 18556 | K43: 295 | L43: 260490.71
A44: 1675 | B44: Back to College Offer | C44: You Tube | D44: 23-Jul-2024 | E44: 22-Aug-2024 | F44: Female 18-24 | G44: East | H44: 70828.98 | I44: 1827028 | J44: 58907 | K44: 1479 | L44: 905251.01
A45: 1702 | B45: Wedding Season Special | C45: e-mail | D45: 07/07/2024 | E45: 04/08/2024 | F45: Female 35-44 | G45: South | H45: 4022.16 | I45: 90484 | J45: 567 | K45: 21 | L45: 34140.06
A46: 1033 | B46: Clearance Sale Push | C46: email | D46: 11-Aug-2024 | E46: 08-Sep-2024 | F46: Male 45+ | G46: Centrl | H46: 2878.77 | I46: 104478 | J46: 3126 | K46: 50 | L46: 81418.26
...

Sheet Lookup_Tables
A1: Channel_Variant | B1: Channel_Clean | C1: Match_Key | E1: Region_Variant | F1: Region_Clean | G1: Match_Key
A2: INSTAGRAM | B2: Instagram | C2: =UPPER(TRIM(A2)) -> INSTAGRAM | E2: Nort | F2: North | G2: =UPPER(TRIM(E2)) -> NORT
A3: Instagram | B3: Instagram | C3: =UPPER(TRIM(A3)) -> INSTAGRAM | E3: NORTH | F3: North | G3: =UPPER(TRIM(E3)) -> NORTH
A4: Instagram | B4: Instagram | C4: =UPPER(TRIM(A4)) -> INSTAGRAM | E4: north | F4: North | G4: =UPPER(TRIM(E4)) -> NORTH
A5: Insta | B5: Instagram | C5: =UPPER(TRIM(A5)) -> INSTA | E5: North | F5: North | G5: =UPPER(TRIM(E5)) -> NORTH
A6: instagram | B6: Instagram | C6: =UPPER(TRIM(A6)) -> INSTAGRAM | E6: North | F6: North | G6: =UPPER(TRIM(E6)) -> NORTH
A7: FB | B7: Facebook | C7: =UPPER(TRIM(A7)) -> FB | E7: South | F7: South | G7: =UPPER(TRIM(E7)) -> SOUTH
A8: Facebook | B8: Facebook | C8: =UPPER(TRIM(A8)) -> FACEBOOK | E8: south | F8: South | G8: =UPPER(TRIM(E8)) -> SOUTH
A9: FACEBOOK | B9: Facebook | C9: =UPPER(TRIM(A9)) -> FACEBOOK | E9: South | F9: South | G9: =UPPER(TRIM(E9)) -> SOUTH
A10: Facebook | B10: Facebook | C10: =UPPER(TRIM(A10)) -> FACEBOOK | E10: SOUTH | F10: South | G10: =UPPER(TRIM(E10)) -> SOUTH
A11: facebook | B11: Facebook | C11: =UPPER(TRIM(A11)) -> FACEBOOK | E11: East | F11: East | G11: =UPPER(TRIM(E11)) -> EAST
A12: Google Ads | B12: Google Ads | C12: =UPPER(TRIM(A12)) -> GOOGLE ADS | E12: EAST | F12: East | G12: =UPPER(TRIM(E12)) -> EAST
A13: google ads | B13: Google Ads | C13: =UPPER(TRIM(A13)) -> GOOGLE ADS | E13: east | F13: East | G13: =UPPER(TRIM(E13)) -> EAST
... A24: YouTube | B24: YouTube | C24: =UPPER(TRIM(A24)) -> YOUTUBE | E24: Central | F24: Central | G24: =UPPER(TRIM(E24)) -> CENTRAL
A25: YOUTUBE | B25: YouTube | C25: =UPPER(TRIM(A25)) -> YOUTUBE
A26: youtube | B26: YouTube | C26: =UPPER(TRIM(A26)) -> YOUTUBE

Sheet Cleaned_Data
A1: Campaign_ID | B1: Campaign_Name_Clean | C1: Channel_Clean | D1: Start_Date_Clean | E1: End_Date_Clean | F1: Target_Audience | G1: Region_Clean | H1: Spend_Filled | I1: Impressions | J1: Clicks_Fixed | K1: Conversions | L1: Revenue_Filled | M1: CTR | N1: CPC | O1: CPA | P1: ROAS | Q1: Conversion_Rate | R1: Duplicate_Flag | S1: Data_Quality_Note
A2: =Raw_Data!A2 -> 1179 | B2: =PROPER(TRIM(Raw_Data!B2)) -> Ayurvedic Range Launch | C2: =IFERROR(INDEX(Lookup_Tables!$B$2:$B$26,MATCH(UPPER(TRIM(Raw_Data!C2)),Lookup_Tables!$C$2:$C$26,0)),"Unknown") -> Email | D2: =IFERROR(IF(ISNUMBER(SEARCH("/",Raw_Data!D2)),DATE(VALUE(RIGHT(Raw_Data!D2,4)),VALUE(MID(Raw_Data!D2,FIND("/",Raw_Data!D2)+1,FIND("/",Raw_Data!D2,FIND("/",Raw_Data!D2)+1)-FIND("/",Raw_Data!D2)-1)),VALUE(LEFT(Raw_Data!D2,FIND("/",Raw_Data!D2)-1))),IF(ISNUMBER(VALUE(LEFT(Raw_Data!D2,4))),DATE(VALUE(LEFT(Raw_Data!D2,4)),VALUE(MID(Raw_Data!D2,6,2)),VALUE(MID(Raw_Data!D2,9,2))),DATEVALUE(Raw_Data!D2))),"") -> 45320 | E2: =IFERROR(IF(ISNUMBER(SEARCH("/",Raw_Data!E2)),DATE(VALUE(RIGHT(Raw_Data!E2,4)),VALUE(MID(Raw_Data!E2,FIND("/",Raw_Data!E2)+1,FIND("/",Raw_Data!E2,FIND("/",Raw_Data!E2)+1)-FIND("/",Raw_Data!E2)-1)),VALUE(LEFT(Raw_Data!E2,FIND("/",Raw_Data!E2)-1))),IF(ISNUMBER(VALUE(LEFT(Raw_Data!E2,4))),DATE(VALUE(LEFT(Raw_Data!E2,4)),VALUE(MID(Raw_Data!E2,6,2)),VALUE(MID(Raw_Data!E2,9,2))),DATEVALUE(Raw_Data!E2))),"") -> 45341 | F2: =Raw_Data!F2 -> Male 35-44 | G2: =IF(TRIM(Raw_Data!G2)="","Unspecified",IFERROR(INDEX(Lookup_Tables!$F$2:$F$24,MATCH(UPPER(TRIM(Raw_Data!G2)),Lookup_Tables!$G$2:$G$24,0)),"Unknown")) -> West | H2: =IF(Raw_Data!H2="",ROUND(AVERAGEIFS(Raw_Data!$H$2:$H$839,Raw_Data!$C$2:$C$839,Raw_Data!C2),2),Raw_Data!H2) -> 1459.32 | I2: =Raw_Data!I2 -> 47777 | J2: =IF(Raw_Data!J2<0,ABS(Raw_Data!J2),Raw_Data!J2) -> 817 | K2: =Raw_Data!K2 -> 52 | L2: =IF(Raw_Data!L2="",ROUND(AVERAGEIFS(Raw_Data!$L$2:$L$839,Raw_Data!$C$2:$C$839,Raw_Data!C2),2),Raw_Data!L2) -> 57731.18 | M2: =IFERROR(J2/I2,0) -> 0.017100278 | N2: =IFERROR(H2/J2,0) -> 1.7861934 | O2: =IFERROR(H2/K2,0) -> 28.063846 | P2: =IFERROR(L2/H2,0) -> 39.560329 | Q2: =IFERROR(K2/J2,0) -> 0.063647491 | R2: =IF(COUNTIF($A$2:A2,A2)>1,"Duplicate - Remove","Unique") -> Unique | S2: =TRIM(IF(Raw_Data!G2="","Region missing; ","")&IF(Raw_Data!H2="","Spend imputed; ","")&IF(Raw_Data!L2="","Revenue imputed; ","")&IF(Raw_Data!J2<0,"Clicks corrected; ",""))
A3: =Raw_Data!A3 -> 1665 | B3: =PROPER(TRIM(Raw_Data!B3)) -> Ayurvedic Range Launch | C3: =IFERROR(INDEX(Lookup_Tables!$B$2:$B$26,MATCH(UPPER(TRIM(Raw_Data!C3)),Lookup_Tables!$C$2:$C$26,0)),"Unknown") -> Google Ads | D3: =IFERROR(IF(ISNUMBER(SEARCH("/",Raw_Data!D3)),DATE(VALUE(RIGHT(Raw_Data!D3,4)),VALUE(MID(Raw_Data!D3,FIND("/",Raw_Data!D3)+1,FIND("/",Raw_Data!D3,FIND("/",Raw_Data!D3)+1)-FIND("/",Raw_Data!D3)-1)),VALUE(LEFT(Raw_Data!D3,FIND("/",Raw_Data!D3)-1))),IF(ISNUMBER(VALUE(LEFT(Raw_Data!D3,4))),DATE(VALUE(LEFT(Raw_Data!D3,4)),VALUE(MID(Raw_Data!D3,6,2)),VALUE(MID(Raw_Data!D3,9,2))),DATEVALUE(Raw_Data!D3))),"") -> 45610 | E3: =IFERROR(IF(ISNUMBER(SEARCH("/",Raw_Data!E3)),DATE(VALUE(RIGHT(Raw_Data!E3,4)),VALUE(MID(Raw_Data!E3,FIND("/",Raw_Data!E3)+1,FIND("/",Raw_Data!E3,FIND("/",Raw_Data!E3)+1)-FIND("/",Raw_Data!E3)-1)),VALUE(LEFT(Raw_Data!E3,FIND("/",Raw_Data!E3)-1))),IF(ISNUMBER(VALUE(LEFT(Raw_Data!E3,4))),DATE(VALUE(LEFT(Raw_Data!E3,4)),VALUE(MID(Raw_Data!E3,6,2)),VALUE(MID(Raw_Data!E3,9,2))),DATEVALUE(Raw_Data!E3))),"") -> 45623 | F3: =Raw_Data!F3 -> Male 45+ | G3: =IF(TRIM(Raw_Data!G3)="","Unspecified",IFERROR(INDEX(Lookup_Tables!$F$2:$F$24,MATCH(UPPER(TRIM(Raw_Data!G3)),Lookup_Tables!$G$2:$G$24,0)),"Unknown")) -> West | H3: =IF(Raw_Data!H3="",ROUND(AVERAGEIFS(Raw_Data!$H$2:$H$839,Raw_Data!$C$2:$C$839,Raw_Data!C3),2),Raw_Data!H3) -> 40790.41 | I3: =Raw_Data!I3 -> 1371537 | J3: =IF(Raw_Data!J3<0,ABS(Raw_Data!J3),Raw_Data!J3) -> 33827 | K3: =Raw_Data!K3 -> 1556 | L3: =IF(Raw_Data!L3="",ROUND(AVERAGEIFS(Raw_Data!$L$2:$L$839,Raw_Data!$C$2:$C$839,Raw_Data!C3),2),Raw_Data!L3) -> 1305729.8 | M3: =IFERROR(J3/I3,0) -> 0.024663571 | N3: =IFERROR(H3/J3,0) -> 1.2058536 | O3: =IFERROR(H3/K3,0) -> 26.214916 | P3: =IFERROR(L3/H3,0) -> 32.010706 | Q3: =IFERROR(K3/J3,0) -> 0.045998758 | R3: =IF(COUNTIF($A$2:A3,A3)>1,"Duplicate - Remove","Unique") -> Unique | S3: =TRIM(IF(Raw_Data!G3="","Region missing; ","")&IF(Raw_Data!H3="","Spend imputed; ","")&IF(Raw_Data!L3="","Revenue imputed; ","")&IF(Raw_Data!J3<0,"Clicks corrected; ",""))
A4: =Raw_Data!A4 -> 1798 | B4: =PROPER(TRIM(Raw_Data!B4)) -> Herbal Range Awareness | C4: =IFERROR(INDEX(Lookup_Tables!$B$2:$B$26,MATCH(UPPER(TRIM(Raw_Data!C4)),Lookup_Tables!$C$2:$C$26,0)),"Unknown") -> Email | D4: =IFERROR(IF(ISNUMBER(SEARCH("/",Raw_Data!D4)),DATE(VALUE(RIGHT(Raw_Data!D4,4)),VALUE(MID(Raw_Data!D4,FIND("/",Raw_Data!D4)+1,FIND("/",Raw_Data!D4,FIND("/",Raw_Data!D4)+1)-FIND("/",Raw_Data!D4)-1)),VALUE(LEFT(Raw_Data!D4,FIND("/",Raw_Data!D4)-1))),IF(ISNUMBER(VALUE(LEFT(Raw_Data!D4,4))),DATE(VALUE(LEFT(Raw_Data!D4,4)),VALUE(MID(Raw_Data!D4,6,2)),VALUE(MID(Raw_Data!D4,9,2))),DATEVALUE(Raw_Data!D4))),"") -> 45595 | E4: =IFERROR(IF(ISNUMBER(SEARCH("/",Raw_Data!E4)),DATE(VALUE(RIGHT(Raw_Data!E4,4)),VALUE(MID(Raw_Data!E4,FIND("/",Raw_Data!E4)+1,FIND("/",Raw_Data!E4,FIND("/",Raw_Data!E4)+1)-FIND("/",Raw_Data!E4)-1)),VALUE(LEFT(Raw_Data!E4,FIND("/",Raw_Data!E4)-1))),IF(ISNUMBER(VALUE(LEFT(Raw_Data!E4,4))),DATE(VALUE(LEFT(Raw_Data!E4,4)),VALUE(MID(Raw_Data!E4,6,2)),VALUE(MID(Raw_Data!E4,9,2))),DATEVALUE(Raw_Data!E4))),"") -> 45604 | F4: =Raw_Data!F4 -> Female 25-34 | G4: =IF(TRIM(Raw_Data!G4)="","Unspecified",IFERROR(INDEX(Lookup_Tables!$F$2:$F$24,MATCH(UPPER(TRIM(Raw_Data!G4)),Lookup_Tables!$G$2:$G$24,0)),"Unknown")) -> North | H4: =IF(Raw_Data!H4="",ROUND(AVERAGEIFS(Raw_Data!$H$2:$H$839,Raw_Data!$C$2:$C$839,Raw_Data!C4),2),Raw_Data!H4) -> 4460.42 | I4: =Raw_Data!I4 -> 177985 | J4: =IF(Raw_Data!J4<0,ABS(Raw_Data!J4),Raw_Data!J4) -> 4765 | K4: =Raw_Data!K4 -> 161 | L4: =IF(Raw_Data!L4="",ROUND(AVERAGEIFS(Raw_Data!$L$2:$L$839,Raw_Data!$C$2:$C$839,Raw_Data!C4),2),Raw_Data!L4) -> 110861.2 | M4: =IFERROR(J4/I4,0) -> 0.026771919 | N4: =IFERROR(H4/J4,0) -> 0.93607975 | O4: =IFERROR(H4/K4,0) -> 27.704472 | P4: =IFERROR(L4/H4,0) -> 24.854431 | Q4: =IFERROR(K4/J4,0) -> 0.033788038 | R4: =IF(COUNTIF($A$2:A4,A4)>1,"Duplicate - Remove","Unique") -> Unique | S4: =TRIM(IF(Raw_Data!G4="","Region missing; ","")&IF(Raw_Data!H4="","Spend imputed; ","")&IF(Raw_Data!L4="","Revenue imputed; ","")&IF(Raw_Data!J4<0,"Clicks corrected; ","")) -> Revenue imputed;
A5: =Raw_Data!A5 -> 1396 | B5: =PROPER(TRIM(Raw_Data!B5)) -> Clearance Sale Push | C5: =IFERROR(INDEX(Lookup_Tables!$B$2:$B$26,MATCH(UPPER(TRIM(Raw_Data!C5)),Lookup_Tables!$C$2:$C$26,0)),"Unknown") -> Email | D5: =IFERROR(IF(ISNUMBER(SEARCH("/",Raw_Data!D5)),DATE(VALUE(RIGHT(Raw_Data!D5,4)),VALUE(MID(Raw_Data!D5,FIND("/",Raw_Data!D5)+1,FIND("/",Raw_Data!D5,FIND("/",Raw_Data!D5)+1)-FIND("/",Raw_Data!D5)-1)),VALUE(LEFT(Raw_Data!D5,FIND("/",Raw_Data!D5)-1))),IF(ISNUMBER(VALUE(LEFT(Raw_Data!D5,4))),DATE(VALUE(LEFT(Raw_Data!D5,4)),VALUE(MID(Raw_Data!D5,6,2)),VALUE(MID(Raw_Data!D5,9,2))),DATEVALUE(Raw_Data!D5))),"") -> 45540 | E5: =IFERROR(IF(ISNUMBER(SEARCH("/",Raw_Data!E5)),DATE(VALUE(RIGHT(Raw_Data!E5,4)),VALUE(MID(Raw_Data!E5,FIND("/",Raw_Data!E5)+1,FIND("/",Raw_Data!E5,FIND("/",Raw_Data!E5)+1)-FIND("/",Raw_Data!E5)-1)),VALUE(LEFT(Raw_Data!E5,FIND("/",Raw_Data!E5)-1))),IF(ISNUMBER(VALUE(LEFT(Raw_Data!E5,4))),DATE(VALUE(LEFT(Raw_Data!E5,4)),VALUE(MID(Raw_Data!E5,6,2)),VALUE(MID(Raw_Data!E5,9,2))),DATEVALUE(Raw_Data!E5))),"") -> 45567 | F5: =Raw_Data!F5 -> Female 35-44 | G5: =IF(TRIM(Raw_Data!G5)="","Unspecified",IFERROR(INDEX(Lookup_Tables!$F$2:$F$24,MATCH(UPPER(TRIM(Raw_Data!G5)),Lookup_Tables!$G$2:$G$24,0)),"Unknown")) -> West | H5: =IF(Raw_Data!H5="",ROUND(AVERAGEIFS(Raw_Data!$H$2:$H$839,Raw_Data!$C$2:$C$839,Raw_Data!C5),2),Raw_Data!H5) -> 1905.7 | I5: =Raw_Data!I5 -> 62150 | J5: =IF(Raw_Data!J5<0,ABS(Raw_Data!J5),Raw_Data!J5) -> 1920 | K5: =Raw_Data!K5 -> 35 | L5: =IF(Raw_Data!L5="",ROUND(AVERAGEIFS(Raw_Data!$L$2:$L$839,Raw_Data!$C$2:$C$839,Raw_Data!C5),2),Raw_Data!L5) -> 23041.61 | M5: =IFERROR(J5/I5,0) -> 0.030893001 | N5: =IFERROR(H5/J5,0) -> 0.99255208 | O5: =IFERROR(H5/K5,0) -> 54.448571 | P5: =IFERROR(L5/H5,0) -> 12.09089 | Q5: =IFERROR(K5/J5,0) -> 0.018229167 | R5: =IF(COUNTIF($A$2:A5,A5)>1,"Duplicate - Remove","Unique") -> Unique | S5: =TRIM(IF(Raw_Data!G5="","Region missing; ","")&IF(Raw_Data!H5="","Spend imputed; ","")&IF(Raw_Data!L5="","Revenue imputed; ","")&IF(Raw_Data!J5<0,"Clicks corrected; ",""))
A6: =Raw_Data!A6 -> 1160 | B6: =PROPER(TRIM(Raw_Data!B6)) -> Ayurvedic Range Launch | C6: =IFERROR(INDEX(Lookup_Tables!$B$2:$B$26,MATCH(UPPER(TRIM(Raw_Data!C6)),Lookup_Tables!$C$2:$C$26,0)),"Unknown") -> Email | D6: =IFERROR(IF(ISNUMBER(SEARCH("/",Raw_Data!D6)),DATE(VALUE(RIGHT(Raw_Data!D6,4)),VALUE(MID(Raw_Data!D6,FIND("/",Raw_Data!D6)+1,FIND("/",Raw_Data!D6,FIND("/",Raw_Data!D6)+1)-FIND("/",Raw_Data!D6)-1)),VALUE(LEFT(Raw_Data!D6,FIND("/",Raw_Data!D6)-1))),IF(ISNUMBER(VALUE(LEFT(Raw_Data!D6,4))),DATE(VALUE(LEFT(Raw_Data!D6,4)),VALUE(MID(Raw_Data!D6,6,2)),VALUE(MID(Raw_Data!D6,9,2))),DATEVALUE(Raw_Data!D6))),"") -> 45303 | E6: =IFERROR(IF(ISNUMBER(SEARCH("/",Raw_Data!E6)),DATE(VALUE(RIGHT(Raw_Data!E6,4)),VALUE(MID(Raw_Data!E6,FIND("/",Raw_Data!E6)+1,FIND("/",Raw_Data!E6,FIND("/",Raw_Data!E6)+1)-FIND("/",Raw_Data!E6)-1)),VALUE(LEFT(Raw_Data!E6,FIND("/",Raw_Data!E6)-1))),IF(ISNUMBER(VALUE(LEFT(Raw_Data!E6,4))),DATE(VALUE(LEFT(Raw_Data!E6,4)),VALUE(MID(Raw_Data!E6,6,2)),VALUE(MID(Raw_Data!E6,9,2))),DATEVALUE(Raw_Data!E6))),"") -> 45310 | F6: =Raw_Data!F6 -> Female 25-34 | G6: =IF(TRIM(Raw_Data!G6)="","Unspecified",IFERROR(INDEX(Lookup_Tables!$F$2:$F$24,MATCH(UPPER(TRIM(Raw_Data!G6)),Lookup_Tables!$G$2:$G$24,0)),"Unknown")) -> Central | H6: =IF(Raw_Data!H6="",ROUND(AVERAGEIFS(Raw_Data!$H$2:$H$839,Raw_Data!$C$2:$C$839,Raw_Data!C6),2),Raw_Data!H6) -> 7317.47 | I6: =Raw_Data!I6 -> 190881 | J6: =IF(Raw_Data!J6<0,ABS(Raw_Data!J6),Raw_Data!J6) -> 1691 | K6: =Raw_Data!K6 -> 124 | L6: =IF(Raw_Data!L6="",ROUND(AVERAGEIFS(Raw_Data!$L$2:$L$839,Raw_Data!$C$2:$C$839,Raw_Data!C6),2),Raw_Data!L6) -> 192518.24 | M6: =IFERROR(J6/I6,0) -> 0.0088589226 | N6: =IFERROR(H6/J6,0) -> 4.3273034 | O6: =IFERROR(H6/K6,0) -> 59.011855 | P6: =IFERROR(L6/H6,0) -> 26.309399 | Q6: =IFERROR(K6/J6,0) -> 0.073329391 | R6: =IF(COUNTIF($A$2:A6,A6)>1,"Duplicate - Remove","Unique") -> Unique | S6: =TRIM(IF(Raw_Data!G6="","Region missing; ","")&IF(Raw_Data!H6="","Spend imputed; ","")&IF(Raw_Data!L6="","Revenue imputed; ","")&IF(Raw_Data!J6<0,"Clicks corrected; ",""))
A7: =Raw_Data!A7 -> 1429 | B7: =PROPER(TRIM(Raw_Data!B7)) -> Baby Care Trust Campaign | C7: =IFERROR(INDEX(Lookup_Tables!$B$2:$B$26,MATCH(UPPER(TRIM(Raw_Data!C7)),Lookup_Tables!$C$2:$C$26,0)),"Unknown") -> YouTube | D7: =IFERROR(IF(ISNUMBER(SEARCH("/",Raw_Data!D7)),DATE(VALUE(RIGHT(Raw_Data!D7,4)),VALUE(MID(Raw_Data!D7,FIND("/",Raw_Data!D7)+1,FIND("/",Raw_Data!D7,FIND("/",Raw_Data!D7)+1)-FIND("/",Raw_Data!D7)-1)),VALUE(LEFT(Raw_Data!D7,FIND("/",Raw_Data!D7)-1))),IF(ISNUMBER(VALUE(LEFT(Raw_Data!D7,4))),DATE(VALUE(LEFT(Raw_Data!D7,4)),VALUE(MID(Raw_Data!D7,6,2)),VALUE(MID(Raw_Data!D7,9,2))),DATEVALUE(Raw_Data!D7))),"") -> 45388 | E7: =IFERROR(IF(ISNUMBER(SEARCH("/",Raw_Data!E7)),DATE(VALUE(RIGHT(Raw_Data!E7,4)),VALUE(MID(Raw_Data!E7,FIND("/",Raw_Data!E7)+1,FIND("/",Raw_Data!E7,FIND("/",Raw_Data!E7)+1)-FIND("/",Raw_Data!E7)-1)),VALUE(LEFT(Raw_Data!E7,FIND("/",Raw_Data!E7)-1))),IF(ISNUMBER(VALUE(LEFT(Raw_Data!E7,4))),DATE(VALUE(LEFT(Raw_Data!E7,4)),VALUE(MID(Raw_Data!E7,6,2)),VALUE(MID(Raw_Data!E7,9,2))),DATEVALUE(Raw_Data!E7))),"") -> 45408 | F7: =Raw_Data!F7 -> Female 45+ | G7: =IF(TRIM(Raw_Data!G7)="","Unspecified",IFERROR(INDEX(Lookup_Tables!$F$2:$F$24,MATCH(UPPER(TRIM(Raw_Data!G7)),Lookup_Tables!$G$2:$G$24,0)),"Unknown")) -> South | H7: =IF(Raw_Data!H7="",ROUND(AVERAGEIFS(Raw_Data!$H$2:$H$839,Raw_Data!$C$2:$C$839,Raw_Data!C7),2),Raw_Data!H7) -> 39663.1 | I7: =Raw_Data!I7 -> 1548782 | J7: =IF(Raw_Data!J7<0,ABS(Raw_Data!J7),Raw_Data!J7) -> 37434 | K7: =Raw_Data!K7 -> 1172 | L7: =IF(Raw_Data!L7="",ROUND(AVERAGEIFS(Raw_Data!$L$2:$L$839,Raw_Data!$C$2:$C$839,Raw_Data!C7),2),Raw_Data!L7) -> 701517.37 | M7: =IFERROR(J7/I7,0) -> 0.024169961 | N7: =IFERROR(H7/J7,0) -> 1.0595475 | O7: =IFERROR(H7/K7,0) -> 33.842235 | P7: =IFERROR(L7/H7,0) -> 17.686902 | Q7: =IFERROR(K7/J7,0) -> 0.031308436 | R7: =IF(COUNTIF($A$2:A7,A7)>1,"Duplicate - Remove","Unique") -> Unique | S7: =TRIM(IF(Raw_Data!G7="","Region missing; ","")&IF(Raw_Data!H7="","Spend imputed; ","")&IF(Raw_Data!L7="","Revenue imputed; ","")&IF(Raw_Data!J7<0,"Clicks corrected; ",""))
A8: =Raw_Data!A8 -> 1077 | B8: =PROPER(TRIM(Raw_Data!B8)) -> Festive Gift Bundle | C8: =IFERROR(INDEX(Lookup_Tables!$B$2:$B$26,MATCH(UPPER(TRIM(Raw_Data!C8)),Lookup_Tables!$C$2:$C$26,0)),"Unknown") -> Facebook | D8: =IFERROR(IF(ISNUMBER(SEARCH("/",Raw_Data!D8)),DATE(VALUE(RIGHT(Raw_Data!D8,4)),VALUE(MID(Raw_Data!D8,FIND("/",Raw_Data!D8)+1,FIND("/",Raw_Data!D8,FIND("/",Raw_Data!D8)+1)-FIND("/",Raw_Data!D8)-1)),VALUE(LEFT(Raw_Data!D8,FIND("/",Raw_Data!D8)-1))),IF(ISNUMBER(VALUE(LEFT(Raw_Data!D8,4))),DATE(VALUE(LEFT(Raw_Data!D8,4)),VALUE(MID(Raw_Data!D8,6,2)),VALUE(MID(Raw_Data!D8,9,2))),DATEVALUE(Raw_Data!D8))),"") -> 45556 | E8: =IFERROR(IF(ISNUMBER(SEARCH("/",Raw_Data!E8)),DATE(VALUE(RIGHT(Raw_Data!E8,4)),VALUE(MID(Raw_Data!E8,FIND("/",Raw_Data!E8)+1,FIND("/",Raw_Data!E8,FIND("/",Raw_Data!E8)+1)-FIND("/",Raw_Data!E8)-1)),VALUE(LEFT(Raw_Data!E8,FIND("/",Raw_Data!E8)-1))),IF(ISNUMBER(VALUE(LEFT(Raw_Data!E8,4))),DATE(VALUE(LEFT(Raw_Data!E8,4)),VALUE(MID(Raw_Data!E8,6,2)),VALUE(MID(Raw_Data!E8,9,2))),DATEVALUE(Raw_Data!E8))),"") -> 45564 | F8: =Raw_Data!F8 -> Female 25-34 | G8: =IF(TRIM(Raw_Data!G8)="","Unspecified",IFERROR(INDEX(Lookup_Tables!$F$2:$F$24,MATCH(UPPER(TRIM(Raw_Data!G8)),Lookup_Tables!$G$2:$G$24,0)),"Unknown")) -> West | H8: =IF(Raw_Data!H8="",ROUND(AVERAGEIFS(Raw_Data!$H$2:$H$839,Raw_Data!$C$2:$C$839,Raw_Data!C8),2),Raw_Data!H8) -> 9690.51 | I8: =Raw_Data!I8 -> 184195 | J8: =IF(Raw_Data!J8<0,ABS(Raw_Data!J8),Raw_Data!J8) -> 3403 | K8: =Raw_Data!K8 -> 156 | L8: =IF(Raw_Data!L8="",ROUND(AVERAGEIFS(Raw_Data!$L$2:$L$839,Raw_Data!$C$2:$C$839,Raw_Data!C8),2),Raw_Data!L8) -> 242582.77 | M8: =IFERROR(J8/I8,0) -> 0.018474986 | N8: =IFERROR(H8/J8,0) -> 2.8476374 | O8: =IFERROR(H8/K8,0) -> 62.118654 | P8: =IFERROR(L8/H8,0) -> 25.033024 | Q8: =IFERROR(K8/J8,0) -> 0.045841904 | R8: =IF(COUNTIF($A$2:A8,A8)>1,"Duplicate - Remove","Unique") -> Unique | S8: =TRIM(IF(Raw_Data!G8="","Region missing; ","")&IF(Raw_Data!H8="","Spend imputed; ","")&IF(Raw_Data!L8="","Revenue imputed; ","")&IF(Raw_Data!J8<0,"Clicks corrected; ",""))
A9: =Raw_Data!A9 -> 1595 | B9: =PROPER(TRIM(Raw_Data!B9)) -> Anti-Ageing Serum Push | C9: =IFERROR(INDEX(Lookup_Tables!$B$2:$B$26,MATCH(UPPER(TRIM(Raw_Data!C9)),Lookup_Tables!$C$2:$C$26,0)),"Unknown") -> Email | D9: =IFERROR(IF(ISNUMBER(SEARCH("/",Raw_Data!D9)),DATE(VALUE(RIGHT(Raw_Data!D9,4)),VALUE(MID(Raw_Data!D9,FIND("/",Raw_Data!D9)+1,FIND("/",Raw_Data!D9,FIND("/",Raw_Data!D9)+1)-FIND("/",Raw_Data!D9)-1)),VALUE(LEFT(Raw_Data!D9,FIND("/",Raw_Data!D9)-1))),IF(ISNUMBER(VALUE(LEFT(Raw_Data!D9,4))),DATE(VALUE(LEFT(Raw_Data!D9,4)),VALUE(MID(Raw_Data!D9,6,2)),VALUE(MID(Raw_Data!D9,9,2))),DATEVALUE(Raw_Data!D9))),"") -> 45487 | E9: =IFERROR(IF(ISNUMBER(SEARCH("/",Raw_Data!E9)),DATE(VALUE(RIGHT(Raw_Data!E9,4)),VALUE(MID(Raw_Data!E9,FIND("/",Raw_Data!E9)+1,FIND("/",Raw_Data!E9,FIND("/",Raw_Data!E9)+1)-FIND("/",Raw_Data!E9)-1)),VALUE(LEFT(Raw_Data!E9,FIND("/",Raw_Data!E9)-1))),IF(ISNUMBER(VALUE(LEFT(Raw_Data!E9,4))),DATE(VALUE(LEFT(Raw_Data!E9,4)),VALUE(MID(Raw_Data!E9,6,2)),VALUE(MID(Raw_Data!E9,9,2))),DATEVALUE(Raw_Data!E9))),"") -> 45492 | F9: =Raw_Data!F9 -> Male 18-24 | G9: =IF(TRIM(Raw_Data!G9)="","Unspecified",IFERROR(INDEX(Lookup_Tables!$F$2:$F$24,MATCH(UPPER(TRIM(Raw_Data!G9)),Lookup_Tables!$G$2:$G$24,0)),"Unknown")) -> Central | H9: =IF(Raw_Data!H9="",ROUND(AVERAGEIFS(Raw_Data!$H$2:$H$839,Raw_Data!$C$2:$C$839,Raw_Data!C9),2),Raw_Data!H9) -> 6092.9 | I9: =Raw_Data!I9 -> 236321 | J9: =IF(Raw_Data!J9<0,ABS(Raw_Data!J9),Raw_Data!J9) -> 6588 | K9: =Raw_Data!K9 -> 395 | L9: =IF(Raw_Data!L9="",ROUND(AVERAGEIFS(Raw_Data!$L$2:$L$839,Raw_Data!$C$2:$C$839,Raw_Data!C9),2),Raw_Data!L9) -> 397287.84 | M9: =IFERROR(J9/I9,0) -> 0.027877336 | N9: =IFERROR(H9/J9,0) -> 0.92484821 | O9: =IFERROR(H9/K9,0) -> 15.425063 | P9: =IFERROR(L9/H9,0) -> 65.205048 | Q9: =IFERROR(K9/J9,0) -> 0.059957498 | R9: =IF(COUNTIF($A$2:A9,A9)>1,"Duplicate - Remove","Unique") -> Unique | S9: =TRIM(IF(Raw_Data!G9="","Region missing; ","")&IF(Raw_Data!H9="","Spend imputed; ","")&IF(Raw_Data!L9="","Revenue imputed; ","")&IF(Raw_Data!J9<0,"Clicks corrected; ",""))
A10: =Raw_Data!A10 -> 1784 | B10: =PROPER(TRIM(Raw_Data!B10)) -> Monsoon Skincare Push | C10: =IFERROR(INDEX(Lookup_Tables!$B$2:$B$26,MATCH(UPPER(TRIM(Raw_Data!C10)),Lookup_Tables!$C$2:$C$26,0)),"Unknown") -> Email | D10: =IFERROR(IF(ISNUMBER(SEARCH("/",Raw_Data!D10)),DATE(VALUE(RIGHT(Raw_Data!D10,4)),VALUE(MID(Raw_Data!D10,FIND("/",Raw_Data!D10)+1,FIND("/",Raw_Data!D10,FIND("/",Raw_Data!D10)+1)-FIND("/",Raw_Data!D10)-1)),VALUE(LEFT(Raw_Data!D10,FIND("/",Raw_Data!D10)-1))),IF(ISNUMBER(VALUE(LEFT(Raw_Data!D10,4))),DATE(VALUE(LEFT(Raw_Data!D10,4)),VALUE(MID(Raw_Data!D10,6,2)),VALUE(MID(Raw_Data!D10,9,2))),DATEVALUE(Raw_Data!D10))),"") -> 45362 | E10: =IFERROR(IF(ISNUMBER(SEARCH("/",Raw_Data!E10)),DATE(VALUE(RIGHT(Raw_Data!E10,4)),VALUE(MID(Raw_Data!E10,FIND("/",Raw_Data!E10)+1,FIND("/",Raw_Data!E10,FIND("/",Raw_Data!E10)+1)-FIND("/",Raw_Data!E10)-1)),VALUE(LEFT(Raw_Data!E10,FIND("/",Raw_Data!E10)-1))),IF(ISNUMBER(VALUE(LEFT(Raw_Data!E10,4))),DATE(VALUE(LEFT(Raw_Data!E10,4)),VALUE(MID(Raw_Data!E10,6,2)),VALUE(MID(Raw_Data!E10,9,2))),DATEVALUE(Raw_Data!E10))),"") -> 45369 | F10: =Raw_Data!F10 -> Male 25-34 | G10: =IF(TRIM(Raw_Data!G10)="","Unspecified",IFERROR(INDEX(Lookup_Tables!$F$2:$F$24,MATCH(UPPER(TRIM(Raw_Data!G10)),Lookup_Tables!$G$2:$G$24,0)),"Unknown")) -> Central | H10: =IF(Raw_Data!H10="",ROUND(AVERAGEIFS(Raw_Data!$H$2:$H$839,Raw_Data!$C$2:$C$839,Raw_Data!C10),2),Raw_Data!H10) -> 5243.17 | I10: =Raw_Data!I10 -> 112725 | J10: =IF(Raw_Data!J10<0,ABS(Raw_Data!J10),Raw_Data!J10) -> 2739 | K10: =Raw_Data!K10 -> 161 | L10: =IF(Raw_Data!L10="",ROUND(AVERAGEIFS(Raw_Data!$L$2:$L$839,Raw_Data!$C$2:$C$839,Raw_Data!C10),2),Raw_Data!L10) -> 78789.26 | M10: =IFERROR(J10/I10,0) -> 0.024298071 | N10: =IFERROR(H10/J10,0) -> 1.9142643 | O10: =IFERROR(H10/K10,0) -> 32.566273 | P10: =IFERROR(L10/H10,0) -> 15.027028 | Q10: =IFERROR(K10/J10,0) -> 0.058780577 | R10: =IF(COUNTIF($A$2:A10,A10)>1,"Duplicate - Remove","Unique") -> Unique | S10: =TRIM(IF(Raw_Data!G10="","Region missing; ","")&IF(Raw_Data!H10="","Spend imputed; ","")&IF(Raw_Data!L10="","Revenue imputed; ","")&IF(Raw_Data!J10<0,"Clicks corrected; ",""))
A11: =Raw_Data!A11 -> 1326 | B11: =PROPER(TRIM(Raw_Data!B11)) -> Hair Care Revamp | C11: =IFERROR(INDEX(Lookup_Tables!$B$2:$B$26,MATCH(UPPER(TRIM(Raw_Data!C11)),Lookup_Tables!$C$2:$C$26,0)),"Unknown") -> Google Ads | D11: =IFERROR(IF(ISNUMBER(SEARCH("/",Raw_Data!D11)),DATE(VALUE(RIGHT(Raw_Data!D11,4)),VALUE(MID(Raw_Data!D11,FIND("/",Raw_Data!D11)+1,FIND("/",Raw_Data!D11,FIND("/",Raw_Data!D11)+1)-FIND("/",Raw_Data!D11)-1)),VALUE(LEFT(Raw_Data!D11,FIND("/",Raw_Data!D11)-1))),IF(ISNUMBER(VALUE(LEFT(Raw_Data!D11,4))),DATE(VALUE(LEFT(Raw_Data!D11,4)),VALUE(MID(Raw_Data!D11,6,2)),VALUE(MID(Raw_Data!D11,9,2))),DATEVALUE(Raw_Data!D11))),"") -> 45555 | E11: =IFERROR(IF(ISNUMBER(SEARCH("/",Raw_Data!E11)),DATE(VALUE(RIGHT(Raw_Data!E11,4)),VALUE(MID(Raw_Data!E11,FIND("/",Raw_Data!E11)+1,FIND("/",Raw_Data!E11,FIND("/",Raw_Data!E11)+1)-FIND("/",Raw_Data!E11)-1)),VALUE(LEFT(Raw_Data!E11,FIND("/",Raw_Data!E11)-1))),IF(ISNUMBER(VALUE(LEFT(Raw_Data!E11,4))),DATE(VALUE(LEFT(Raw_Data!E11,4)),VALUE(MID(Raw_Data!E11,6,2)),VALUE(MID(Raw_Data!E11,9,2))),DATEVALUE(Raw_Data!E11))),"") -> 45581 | F11: =Raw_Data!F11 -> Female 18-24 | G11: =IF(TRIM(Raw_Data!G11)="","Unspecified",IFERROR(INDEX(Lookup_Tables!$F$2:$F$24,MATCH(UPPER(TRIM(Raw_Data!G11)),Lookup_Tables!$G$2:$G$24,0)),"Unknown")) -> North | H11: =IF(Raw_Data!H11="",ROUND(AVERAGEIFS(Raw_Data!$H$2:$H$839,Raw_Data!$C$2:$C$839,Raw_Data!C11),2),Raw_Data!H11) -> 72158.45 | I11: =Raw_Data!I11 -> 1282556 | J11: =IF(Raw_Data!J11<0,ABS(Raw_Data!J11),Raw_Data!J11) -> 20479 | K11: =Raw_Data!K11 -> 1092 | L11: =IF(Raw_Data!L11="",ROUND(AVERAGEIFS(Raw_Data!$L$2:$L$839,Raw_Data!$C$2:$C$839,Raw_Data!C11),2),Raw_Data!L11) -> 961045.35 | M11: =IFERROR(J11/I11,0) -> 0.015967334 | N11: =IFERROR(H11/J11,0) -> 3.5235339 | O11: =IFERROR(H11/K11,0) -> 66.079167 | P11: =IFERROR(L11/H11,0) -> 13.318542 | Q11: =IFERROR(K11/J11,0) -> 0.053322916 | R11: =IF(COUNTIF($A$2:A11,A11)>1,"Duplicate - Remove","Unique") -> Unique | S11: =TRIM(IF(Raw_Data!G11="","Region missing; ","")&IF(Raw_Data!H11="","Spend imputed; ","")&IF(Raw_Data!L11="","Revenue imputed; ","")&IF(Raw_Data!J11<0,"Clicks corrected; ",""))
A12: =Raw_Data!A12 -> 1457 | B12: =PROPER(TRIM(Raw_Data!B12)) -> Influencer Collab - Skincare | C12: =IFERROR(INDEX(Lookup_Tables!$B$2:$B$26,MATCH(UPPER(TRIM(Raw_Data!C12)),Lookup_Tables!$C$2:$C$26,0)),"Unknown") -> Google Ads | D12: =IFERROR(IF(ISNUMBER(SEARCH("/",Raw_Data!D12)),DATE(VALUE(RIGHT(Raw_Data!D12,4)),VALUE(MID(Raw_Data!D12,FIND("/",Raw_Data!D12)+1,FIND("/",Raw_Data!D12,FIND("/",Raw_Data!D12)+1)-FIND("/",Raw_Data!D12)-1)),VALUE(LEFT(Raw_Data!D12,FIND("/",Raw_Data!D12)-1))),IF(ISNUMBER(VALUE(LEFT(Raw_Data!D12,4))),DATE(VALUE(LEFT(Raw_Data!D12,4)),VALUE(MID(Raw_Data!D12,6,2)),VALUE(MID(Raw_Data!D12,9,2))),DATEVALUE(Raw_Data!D12))),"") -> 45338 | E12: =IFERROR(IF(ISNUMBER(SEARCH("/",Raw_Data!E12)),DATE(VALUE(RIGHT(Raw_Data!E12,4)),VALUE(MID(Raw_Data!E12,FIND("/",Raw_Data!E12)+1,FIND("/",Raw_Data!E12,FIND("/",Raw_Data!E12)+1)-FIND("/",Raw_Data!E12)-1)),VALUE(LEFT(Raw_Data!E12,FIND("/",Raw_Data!E12)-1))),IF(ISNUMBER(VALUE(LEFT(Raw_Data!E12,4))),DATE(VALUE(LEFT(Raw_Data!E12,4)),VALUE(MID(Raw_Data!E12,6,2)),VALUE(MID(Raw_Data!E12,9,2))),DATEVALUE(Raw_Data!E12))),"") -> 45368 | F12: =Raw_Data!F12 -> Male 45+ | G12: =IF(TRIM(Raw_Data!G12)="","Unspecified",IFERROR(INDEX(Lookup_Tables!$F$2:$F$24,MATCH(UPPER(TRIM(Raw_Data!G12)),Lookup_Tables!$G$2:$G$24,0)),"Unknown")) -> West | H12: =IF(Raw_Data!H12="",ROUND(AVERAGEIFS(Raw_Data!$H$2:$H$839,Raw_Data!$C$2:$C$839,Raw_Data!C12),2),Raw_Data!H12) -> 33296.08 | I12: =Raw_Data!I12 -> 685737 | J12: =IF(Raw_Data!J12<0,ABS(Raw_Data!J12),Raw_Data!J12) -> 15277 | K12: =Raw_Data!K12 -> 1140 | L12: =IF(Raw_Data!L12="",ROUND(AVERAGEIFS(Raw_Data!$L$2:$L$839,Raw_Data!$C$2:$C$839,Raw_Data!C12),2),Raw_Data!L12) -> 505894.6 | M12: =IFERROR(J12/I12,0) -> 0.02227822 | N12: =IFERROR(H12/J12,0) -> 2.1794907 | O12: =IFERROR(H12/K12,0) -> 29.207088 | P12: =IFERROR(L12/H12,0) -> 15.193819 | Q12: =IFERROR(K12/J12,0) -> 0.074621981 | R12: =IF(COUNTIF($A$2:A12,A12)>1,"Duplicate - Remove","Unique") -> Unique | S12: =TRIM(IF(Raw_Data!G12="","Region missing; ","")&IF(Raw_Data!H12="","Spend imputed; ","")&IF(Raw_Data!L12="","Revenue imputed; ","")&IF(Raw_Data!J12<0,"Clicks corrected; ",""))
A13: =Raw_Data!A13 -> 1084 | B13: =PROPER(TRIM(Raw_Data!B13)) -> Monsoon Skincare Push | C13: =IFERROR(INDEX(Lookup_Tables!$B$2:$B$26,MATCH(UPPER(TRIM(Raw_Data!C13)),Lookup_Tables!$C$2:$C$26,0)),"Unknown") -> Instagram | D13: =IFERROR(IF(ISNUMBER(SEARCH("/",Raw_Data!D13)),DATE(VALUE(RIGHT(Raw_Data!D13,4)),VALUE(MID(Raw_Data!D13,FIND("/",Raw_Data!D13)+1,FIND("/",Raw_Data!D13,FIND("/",Raw_Data!D13)+1)-FIND("/",Raw_Data!D13)-1)),VALUE(LEFT(Raw_Data!D13,FIND("/",Raw_Data!D13)-1))),IF(ISNUMBER(VALUE(LEFT(Raw_Data!D13,4))),DATE(VALUE(LEFT(Raw_Data!D13,4)),VALUE(MID(Raw_Data!D13,6,2)),VALUE(MID(Raw_Data!D13,9,2))),DATEVALUE(Raw_Data!D13))),"") -> 45332 | E13: =IFERROR(IF(ISNUMBER(SEARCH("/",Raw_Data!E13)),DATE(VALUE(RIGHT(Raw_Data!E13,4)),VALUE(MID(Raw_Data!E13,FIND("/",Raw_Data!E13)+1,FIND("/",Raw_Data!E13,FIND("/",Raw_Data!E13)+1)-FIND("/",Raw_Data!E13)-1)),VALUE(LEFT(Raw_Data!E13,FIND("/",Raw_Data!E13)-1))),IF(ISNUMBER(VALUE(LEFT(Raw_Data!E13,4))),DATE(VALUE(LEFT(Raw_Data!E13,4)),VALUE(MID(Raw_Data!E13,6,2)),VALUE(MID(Raw_Data!E13,9,2))),DATEVALUE(Raw_Data!E13))),"") -> 45347 | F13: =Raw_Data!F13 -> Female 25-34 | G13: =IF(TRIM(Raw_Data!G13)="","Unspecified",IFERROR(INDEX(Lookup_Tables!$F$2:$F$24,MATCH(UPPER(TRIM(Raw_Data!G13)),Lookup_Tables!$G$2:$G$24,0)),"Unknown")) -> South | H13: =IF(Raw_Data!H13="",ROUND(AVERAGEIFS(Raw_Data!$H$2:$H$839,Raw_Data!$C$2:$C$839,Raw_Data!C13),2),Raw_Data!H13) -> 23373.28 | I13: =Raw_Data!I13 -> 611162 | J13: =IF(Raw_Data!J13<0,ABS(Raw_Data!J13),Raw_Data!J13) -> 16214 | K13: =Raw_Data!K13 -> 351 | L13: =IF(Raw_Data!L13="",ROUND(AVERAGEIFS(Raw_Data!$L$2:$L$839,Raw_Data!$C$2:$C$839,Raw_Data!C13),2),Raw_Data!L13) -> 348777.17 | M13: =IFERROR(J13/I13,0) -> 0.026529791 | N13: =IFERROR(H13/J13,0) -> 1.4415493 | O13: =IFERROR(H13/K13,0) -> 66.590541 | P13: =IFERROR(L13/H13,0) -> 14.922046 | Q13: =IFERROR(K13/J13,0) -> 0.021647959 | R13: =IF(COUNTIF($A$2:A13,A13)>1,"Duplicate - Remove","Unique") -> Unique | S13: =TRIM(IF(Raw_Data!G13="","Region missing; ","")&IF(Raw_Data!H13="","Spend imputed; ","")&IF(Raw_Data!L13="","Revenue imputed; ","")&IF(Raw_Data!J13<0,"Clicks corrected; ",""))
... A839: =Raw_Data!A839 -> 1085 | B839: =PROPER(TRIM(Raw_Data!B839)) -> Men'S Grooming Drive | C839: =IFERROR(INDEX(Lookup_Tables!$B$2:$B$26,MATCH(UPPER(TRIM(Raw_Data!C839)),Lookup_Tables!$C$2:$C$26,0)),"Unknown") -> YouTube | D839: =IFERROR(IF(ISNUMBER(SEARCH("/",Raw_Data!D839)),DATE(VALUE(RIGHT(Raw_Data!D839,4)),VALUE(MID(Raw_Data!D839,FIND("/",Raw_Data!D839)+1,FIND("/",Raw_Data!D839,FIND("/",Raw_Data!D839)+1)-FIND("/",Raw_Data!D839)-1)),VALUE(LEFT(Raw_Data!D839,FIND("/",Raw_Data!D839)-1))),IF(ISNUMBER(VALUE(LEFT(Raw_Data!D839,4))),DATE(VALUE(LEFT(Raw_Data!D839,4)),VALUE(MID(Raw_Data!D839,6,2)),VALUE(MID(Raw_Data!D839,9,2))),DATEVALUE(Raw_Data!D839))),"") -> 45478 | E839: =IFERROR(IF(ISNUMBER(SEARCH("/",Raw_Data!E839)),DATE(VALUE(RIGHT(Raw_Data!E839,4)),VALUE(MID(Raw_Data!E839,FIND("/",Raw_Data!E839)+1,FIND("/",Raw_Data!E839,FIND("/",Raw_Data!E839)+1)-FIND("/",Raw_Data!E839)-1)),VALUE(LEFT(Raw_Data!E839,FIND("/",Raw_Data!E839)-1))),IF(ISNUMBER(VALUE(LEFT(Raw_Data!E839,4))),DATE(VALUE(LEFT(Raw_Data!E839,4)),VALUE(MID(Raw_Data!E839,6,2)),VALUE(MID(Raw_Data!E839,9,2))),DATEVALUE(Raw_Data!E839))),"") -> 45499 | F839: =Raw_Data!F839 -> Female 45+ | G839: =IF(TRIM(Raw_Data!G839)="","Unspecified",IFERROR(INDEX(Lookup_Tables!$F$2:$F$24,MATCH(UPPER(TRIM(Raw_Data!G839)),Lookup_Tables!$G$2:$G$24,0)),"Unknown")) -> North | H839: =IF(Raw_Data!H839="",ROUND(AVERAGEIFS(Raw_Data!$H$2:$H$839,Raw_Data!$C$2:$C$839,Raw_Data!C839),2),Raw_Data!H839) -> 65955.8 | I839: =Raw_Data!I839 -> 2560386 | J839: =IF(Raw_Data!J839<0,ABS(Raw_Data!J839),Raw_Data!J839) -> 23769 | K839: =Raw_Data!K839 -> 1248 | L839: =IF(Raw_Data!L839="",ROUND(AVERAGEIFS(Raw_Data!$L$2:$L$839,Raw_Data!$C$2:$C$839,Raw_Data!C839),2),Raw_Data!L839) -> 1074726.4 | M839: =IFERROR(J839/I839,0) -> 0.0092833659 | N839: =IFERROR(H839/J839,0) -> 2.7748664 | O839: =IFERROR(H839/K839,0) -> 52.849199 | P839: =IFERROR(L839/H839,0) -> 16.294646 | Q839: =IFERROR(K839/J839,0) -> 0.052505364 | R839: =IF(COUNTIF($A$2:A839,A839)>1,"Duplicate - Remove","Unique") -> Unique | S839: =TRIM(IF(Raw_Data!G839="","Region missing; ","")&IF(Raw_Data!H839="","Spend imputed; ","")&IF(Raw_Data!L839="","Revenue imputed; ","")&IF(Raw_Data!J839<0,"Clicks corrected; ","")) -> Revenue imputed;

Sheet Channel_Summary
A1: Channel | B1: Total_Spend | C1: Total_Revenue | D1: Total_Conversions | E1: Total_Clicks | F1: Total_Impressions | G1: Avg_CTR | H1: Avg_CPA | I1: Overall_ROAS
A2: Instagram | B2: =SUMIFS(Cleaned_Data!$H$2:$H$839,Cleaned_Data!$C$2:$C$839,A2,Cleaned_Data!$R$2:$R$839,"Unique") -> 5320153.8 | C2: =SUMIFS(Cleaned_Data!$L$2:$L$839,Cleaned_Data!$C$2:$C$839,A2,Cleaned_Data!$R$2:$R$839,"Unique") -> 1.3941428e+08 | D2: =SUMIFS(Cleaned_Data!$K$2:$K$839,Cleaned_Data!$C$2:$C$839,A2,Cleaned_Data!$R$2:$R$839,"Unique") -> 129870 | E2: =SUMIFS(Cleaned_Data!$J$2:$J$839,Cleaned_Data!$C$2:$C$839,A2,Cleaned_Data!$R$2:$R$839,"Unique") -> 2921888 | F2: =SUMIFS(Cleaned_Data!$I$2:$I$839,Cleaned_Data!$C$2:$C$839,A2,Cleaned_Data!$R$2:$R$839,"Unique") -> 145758458 | G2: =IFERROR(E2/F2,0) -> 0.020046096 | H2: =IFERROR(B2/D2,0) -> 40.965225 | I2: =IFERROR(C2/B2,0) -> 26.204934
A3: Facebook | B3: =SUMIFS(Cleaned_Data!$H$2:$H$839,Cleaned_Data!$C$2:$C$839,A3,Cleaned_Data!$R$2:$R$839,"Unique") -> 4901935.1 | C3: =SUMIFS(Cleaned_Data!$L$2:$L$839,Cleaned_Data!$C$2:$C$839,A3,Cleaned_Data!$R$2:$R$839,"Unique") -> 1.2173872e+08 | D3: =SUMIFS(Cleaned_Data!$K$2:$K$839,Cleaned_Data!$C$2:$C$839,A3,Cleaned_Data!$R$2:$R$839,"Unique") -> 111804 | E3: =SUMIFS(Cleaned_Data!$J$2:$J$839,Cleaned_Data!$C$2:$C$839,A3,Cleaned_Data!$R$2:$R$839,"Unique") -> 2527425 | F3: =SUMIFS(Cleaned_Data!$I$2:$I$839,Cleaned_Data!$C$2:$C$839,A3,Cleaned_Data!$R$2:$R$839,"Unique") -> 129234773 | G3: =IFERROR(E3/F3,0) -> 0.019556849 | H3: =IFERROR(B3/D3,0) -> 43.844004 | I3: =IFERROR(C3/B3,0) -> 24.834829
A4: Google Ads | B4: =SUMIFS(Cleaned_Data!$H$2:$H$839,Cleaned_Data!$C$2:$C$839,A4,Cleaned_Data!$R$2:$R$839,"Unique") -> 7429279.3 | C4: =SUMIFS(Cleaned_Data!$L$2:$L$839,Cleaned_Data!$C$2:$C$839,A4,Cleaned_Data!$R$2:$R$839,"Unique") -> 2.1087396e+08 | D4: =SUMIFS(Cleaned_Data!$K$2:$K$839,Cleaned_Data!$C$2:$C$839,A4,Cleaned_Data!$R$2:$R$839,"Unique") -> 194406 | E4: =SUMIFS(Cleaned_Data!$J$2:$J$839,Cleaned_Data!$C$2:$C$839,A4,Cleaned_Data!$R$2:$R$839,"Unique") -> 4390981 | F4: =SUMIFS(Cleaned_Data!$I$2:$I$839,Cleaned_Data!$C$2:$C$839,A4,Cleaned_Data!$R$2:$R$839,"Unique") -> 207541263 | G4: =IFERROR(E4/F4,0) -> 0.021157147 | H4: =IFERROR(B4/D4,0) -> 38.215278 | I4: =IFERROR(C4/B4,0) -> 28.384174
A5: Email | B5: =SUMIFS(Cleaned_Data!$H$2:$H$839,Cleaned_Data!$C$2:$C$839,A5,Cleaned_Data!$R$2:$R$839,"Unique") -> 765289.51 | C5: =SUMIFS(Cleaned_Data!$L$2:$L$839,Cleaned_Data!$C$2:$C$839,A5,Cleaned_Data!$R$2:$R$839,"Unique") -> 18815718 | D5: =SUMIFS(Cleaned_Data!$K$2:$K$839,Cleaned_Data!$C$2:$C$839,A5,Cleaned_Data!$R$2:$R$839,"Unique") -> 18526 | E5: =SUMIFS(Cleaned_Data!$J$2:$J$839,Cleaned_Data!$C$2:$C$839,A5,Cleaned_Data!$R$2:$R$839,"Unique") -> 420035 | F5: =SUMIFS(Cleaned_Data!$I$2:$I$839,Cleaned_Data!$C$2:$C$839,A5,Cleaned_Data!$R$2:$R$839,"Unique") -> 20445939 | G5: =IFERROR(E5/F5,0) -> 0.020543688 | H5: =IFERROR(B5/D5,0) -> 41.308945 | I5: =IFERROR(C5/B5,0) -> 24.586405
A6: YouTube | B6: =SUMIFS(Cleaned_Data!$H$2:$H$839,Cleaned_Data!$C$2:$C$839,A6,Cleaned_Data!$R$2:$R$839,"Unique") -> 7749587.4 | C6: =SUMIFS(Cleaned_Data!$L$2:$L$839,Cleaned_Data!$C$2:$C$839,A6,Cleaned_Data!$R$2:$R$839,"Unique") -> 2.0549562e+08 | D6: =SUMIFS(Cleaned_Data!$K$2:$K$839,Cleaned_Data!$C$2:$C$839,A6,Cleaned_Data!$R$2:$R$839,"Unique") -> 200418 | E6: =SUMIFS(Cleaned_Data!$J$2:$J$839,Cleaned_Data!$C$2:$C$839,A6,Cleaned_Data!$R$2:$R$839,"Unique") -> 4208690 | F6: =SUMIFS(Cleaned_Data!$I$2:$I$839,Cleaned_Data!$C$2:$C$839,A6,Cleaned_Data!$R$2:$R$839,"Unique") -> 212018612 | G6: =IFERROR(E6/F6,0) -> 0.019850569 | H6: =IFERROR(B6/D6,0) -> 38.667123 | I6: =IFERROR(C6/B6,0) -> 26.516976

Sheet Region_Summary
A1: Region | B1: Total_Spend | C1: Total_Revenue | D1: Total_Conversions | E1: Overall_ROAS
A2: North | B2: =SUMIFS(Cleaned_Data!$H$2:$H$839,Cleaned_Data!$G$2:$G$839,A2,Cleaned_Data!$R$2:$R$839,"Unique") -> 4824757 | C2: =SUMIFS(Cleaned_Data!$L$2:$L$839,Cleaned_Data!$G$2:$G$839,A2,Cleaned_Data!$R$2:$R$839,"Unique") -> 1.2460783e+08 | D2: =SUMIFS(Cleaned_Data!$K$2:$K$839,Cleaned_Data!$G$2:$G$839,A2,Cleaned_Data!$R$2:$R$839,"Unique") -> 119869 | E2: =IFERROR(C2/B2,0) -> 25.826757
A3: South | B3: =SUMIFS(Cleaned_Data!$H$2:$H$839,Cleaned_Data!$G$2:$G$839,A3,Cleaned_Data!$R$2:$R$839,"Unique") -> 4434168.3 | C3: =SUMIFS(Cleaned_Data!$L$2:$L$839,Cleaned_Data!$G$2:$G$839,A3,Cleaned_Data!$R$2:$R$839,"Unique") -> 1.1514629e+08 | D3: =SUMIFS(Cleaned_Data!$K$2:$K$839,Cleaned_Data!$G$2:$G$839,A3,Cleaned_Data!$R$2:$R$839,"Unique") -> 113517 | E3: =IFERROR(C3/B3,0) -> 25.967957
A4: East | B4: =SUMIFS(Cleaned_Data!$H$2:$H$839,Cleaned_Data!$G$2:$G$839,A4,Cleaned_Data!$R$2:$R$839,"Unique") -> 4744840.1 | C4: =SUMIFS(Cleaned_Data!$L$2:$L$839,Cleaned_Data!$G$2:$G$839,A4,Cleaned_Data!$R$2:$R$839,"Unique") -> 1.1761586e+08 | D4: =SUMIFS(Cleaned_Data!$K$2:$K$839,Cleaned_Data!$G$2:$G$839,A4,Cleaned_Data!$R$2:$R$839,"Unique") -> 104607 | E4: =IFERROR(C4/B4,0) -> 24.788162
A5: West | B5: =SUMIFS(Cleaned_Data!$H$2:$H$839,Cleaned_Data!$G$2:$G$839,A5,Cleaned_Data!$R$2:$R$839,"Unique") -> 5868232.6 | C5: =SUMIFS(Cleaned_Data!$L$2:$L$839,Cleaned_Data!$G$2:$G$839,A5,Cleaned_Data!$R$2:$R$839,"Unique") -> 1.6257953e+08 | D5: =SUMIFS(Cleaned_Data!$K$2:$K$839,Cleaned_Data!$G$2:$G$839,A5,Cleaned_Data!$R$2:$R$839,"Unique") -> 151203 | E5: =IFERROR(C5/B5,0) -> 27.705026
A6: Central | B6: =SUMIFS(Cleaned_Data!$H$2:$H$839,Cleaned_Data!$G$2:$G$839,A6,Cleaned_Data!$R$2:$R$839,"Unique") -> 4809854.2 | C6: =SUMIFS(Cleaned_Data!$L$2:$L$839,Cleaned_Data!$G$2:$G$839,A6,Cleaned_Data!$R$2:$R$839,"Unique") -> 1.3263206e+08 | D6: =SUMIFS(Cleaned_Data!$K$2:$K$839,Cleaned_Data!$G$2:$G$839,A6,Cleaned_Data!$R$2:$R$839,"Unique") -> 125603 | E6: =IFERROR(C6/B6,0) -> 27.575068
A7: Unspecified | B7: =SUMIFS(Cleaned_Data!$H$2:$H$839,Cleaned_Data!$G$2:$G$839,A7,Cleaned_Data!$R$2:$R$839,"Unique") -> 1484392.9 | C7: =SUMIFS(Cleaned_Data!$L$2:$L$839,Cleaned_Data!$G$2:$G$839,A7,Cleaned_Data!$R$2:$R$839,"Unique") -> 43756715 | D7: =SUMIFS(Cleaned_Data!$K$2:$K$839,Cleaned_Data!$G$2:$G$839,A7,Cleaned_Data!$R$2:$R$839,"Unique") -> 40225 | E7: =IFERROR(C7/B7,0) -> 29.477853

Sheet Monthly_Trend
A1: Month | B1: Month_Start | C1: Month_End | D1: Total_Spend | E1: Total_Revenue | F1: ROAS
A2: January | B2: =DATE(2024,1,1) -> 45292 | C2: =EOMONTH(B2,0) -> 45322 | D2: =SUMIFS(Cleaned_Data!$H$2:$H$839,Cleaned_Data!$D$2:$D$839,">="&B2,Cleaned_Data!$D$2:$D$839,"<="&C2,Cleaned_Data!$R$2:$R$839,"Unique") -> 1822580.1 | E2: =SUMIFS(Cleaned_Data!$L$2:$L$839,Cleaned_Data!$D$2:$D$839,">="&B2,Cleaned_Data!$D$2:$D$839,"<="&C2,Cleaned_Data!$R$2:$R$839,"Unique") -> 43006093 | F2: =IFERROR(E2/D2,0) -> 23.59627
A3: February | B3: =DATE(2024,2,1) -> 45323 | C3: =EOMONTH(B3,0) -> 45351 | D3: =SUMIFS(Cleaned_Data!$H$2:$H$839,Cleaned_Data!$D$2:$D$839,">="&B3,Cleaned_Data!$D$2:$D$839,"<="&C3,Cleaned_Data!$R$2:$R$839,"Unique") -> 2375983.2 | E3: =SUMIFS(Cleaned_Data!$L$2:$L$839,Cleaned_Data!$D$2:$D$839,">="&B3,Cleaned_Data!$D$2:$D$839,"<="&C3,Cleaned_Data!$R$2:$R$839,"Unique") -> 60678089 | F3: =IFERROR(E3/D3,0) -> 25.538096
A4: March | B4: =DATE(2024,3,1) -> 45352 | C4: =EOMONTH(B4,0) -> 45382 | D4: =SUMIFS(Cleaned_Data!$H$2:$H$839,Cleaned_Data!$D$2:$D$839,">="&B4,Cleaned_Data!$D$2:$D$839,"<="&C4,Cleaned_Data!$R$2:$R$839,"Unique") -> 2450980.1 | E4: =SUMIFS(Cleaned_Data!$L$2:$L$839,Cleaned_Data!$D$2:$D$839,">="&B4,Cleaned_Data!$D$2:$D$839,"<="&C4,Cleaned_Data!$R$2:$R$839,"Unique") -> 59419432 | F4: =IFERROR(E4/D4,0) -> 24.243131
A5: April | B5: =DATE(2024,4,1) -> 45383 | C5: =EOMONTH(B5,0) -> 45412 | D5: =SUMIFS(Cleaned_Data!$H$2:$H$839,Cleaned_Data!$D$2:$D$839,">="&B5,Cleaned_Data!$D$2:$D$839,"<="&C5,Cleaned_Data!$R$2:$R$839,"Unique") -> 2123473.7 | E5: =SUMIFS(Cleaned_Data!$L$2:$L$839,Cleaned_Data!$D$2:$D$839,">="&B5,Cleaned_Data!$D$2:$D$839,"<="&C5,Cleaned_Data!$R$2:$R$839,"Unique") -> 45165194 | F5: =IFERROR(E5/D5,0) -> 21.269486
A6: May | B6: =DATE(2024,5,1) -> 45413 | C6: =EOMONTH(B6,0) -> 45443 | D6: =SUMIFS(Cleaned_Data!$H$2:$H$839,Cleaned_Data!$D$2:$D$839,">="&B6,Cleaned_Data!$D$2:$D$839,"<="&C6,Cleaned_Data!$R$2:$R$839,"Unique") -> 2230568.5 | E6: =SUMIFS(Cleaned_Data!$L$2:$L$839,Cleaned_Data!$D$2:$D$839,">="&B6,Cleaned_Data!$D$2:$D$839,"<="&C6,Cleaned_Data!$R$2:$R$839,"Unique") -> 70772440 | F6: =IFERROR(E6/D6,0) -> 31.728432
A7: June | B7: =DATE(2024,6,1) -> 45444 | C7: =EOMONTH(B7,0) -> 45473 | D7: =SUMIFS(Cleaned_Data!$H$2:$H$839,Cleaned_Data!$D$2:$D$839,">="&B7,Cleaned_Data!$D$2:$D$839,"<="&C7,Cleaned_Data!$R$2:$R$839,"Unique") -> 2726211.8 | E7: =SUMIFS(Cleaned_Data!$L$2:$L$839,Cleaned_Data!$D$2:$D$839,">="&B7,Cleaned_Data!$D$2:$D$839,"<="&C7,Cleaned_Data!$R$2:$R$839,"Unique") -> 93000595 | F7: =IFERROR(E7/D7,0) -> 34.113489
A8: July | B8: =DATE(2024,7,1) -> 45474 | C8: =EOMONTH(B8,0) -> 45504 | D8: =SUMIFS(Cleaned_Data!$H$2:$H$839,Cleaned_Data!$D$2:$D$839,">="&B8,Cleaned_Data!$D$2:$D$839,"<="&C8,Cleaned_Data!$R$2:$R$839,"Unique") -> 2452154.2 | E8: =SUMIFS(Cleaned_Data!$L$2:$L$839,Cleaned_Data!$D$2:$D$839,">="&B8,Cleaned_Data!$D$2:$D$839,"<="&C8,Cleaned_Data!$R$2:$R$839,"Unique") -> 62864533 | F8: =IFERROR(E8/D8,0) -> 25.636451
A9: August | B9: =DATE(2024,8,1) -> 45505 | C9: =EOMONTH(B9,0) -> 45535 | D9: =SUMIFS(Cleaned_Data!$H$2:$H$839,Cleaned_Data!$D$2:$D$839,">="&B9,Cleaned_Data!$D$2:$D$839,"<="&C9,Cleaned_Data!$R$2:$R$839,"Unique") -> 2370652.2 | E9: =SUMIFS(Cleaned_Data!$L$2:$L$839,Cleaned_Data!$D$2:$D$839,">="&B9,Cleaned_Data!$D$2:$D$839,"<="&C9,Cleaned_Data!$R$2:$R$839,"Unique") -> 54198257 | F9: =IFERROR(E9/D9,0) -> 22.862171
A10: September | B10: =DATE(2024,9,1) -> 45536 | C10: =EOMONTH(B10,0) -> 45565 | D10: =SUMIFS(Cleaned_Data!$H$2:$H$839,Cleaned_Data!$D$2:$D$839,">="&B10,Cleaned_Data!$D$2:$D$839,"<="&C10,Cleaned_Data!$R$2:$R$839,"Unique") -> 2339104.6 | E10: =SUMIFS(Cleaned_Data!$L$2:$L$839,Cleaned_Data!$D$2:$D$839,">="&B10,Cleaned_Data!$D$2:$D$839,"<="&C10,Cleaned_Data!$R$2:$R$839,"Unique") -> 74079820 | F10: =IFERROR(E10/D10,0) -> 31.670161
A11: October | B11: =DATE(2024,10,1) -> 45566 | C11: =EOMONTH(B11,0) -> 45596 | D11: =SUMIFS(Cleaned_Data!$H$2:$H$839,Cleaned_Data!$D$2:$D$839,">="&B11,Cleaned_Data!$D$2:$D$839,"<="&C11,Cleaned_Data!$R$2:$R$839,"Unique") -> 2714449.7 | E11: =SUMIFS(Cleaned_Data!$L$2:$L$839,Cleaned_Data!$D$2:$D$839,">="&B11,Cleaned_Data!$D$2:$D$839,"<="&C11,Cleaned_Data!$R$2:$R$839,"Unique") -> 73759954 | F11: =IFERROR(E11/D11,0) -> 27.173078
A12: November | B12: =DATE(2024,11,1) -> 45597 | C12: =EOMONTH(B12,0) -> 45626 | D12: =SUMIFS(Cleaned_Data!$H$2:$H$839,Cleaned_Data!$D$2:$D$839,">="&B12,Cleaned_Data!$D$2:$D$839,"<="&C12,Cleaned_Data!$R$2:$R$839,"Unique") -> 2504171.4 | E12: =SUMIFS(Cleaned_Data!$L$2:$L$839,Cleaned_Data!$D$2:$D$839,">="&B12,Cleaned_Data!$D$2:$D$839,"<="&C12,Cleaned_Data!$R$2:$R$839,"Unique") -> 58209790 | F12: =IFERROR(E12/D12,0) -> 23.24513
A13: December | B13: =DATE(2024,12,1) -> 45627 | C13: =EOMONTH(B13,0) -> 45657 | D13: =SUMIFS(Cleaned_Data!$H$2:$H$839,Cleaned_Data!$D$2:$D$839,">="&B13,Cleaned_Data!$D$2:$D$839,"<="&C13,Cleaned_Data!$R$2:$R$839,"Unique") -> 55915.34 | E13: =SUMIFS(Cleaned_Data!$L$2:$L$839,Cleaned_Data!$D$2:$D$839,">="&B13,Cleaned_Data!$D$2:$D$839,"<="&C13,Cleaned_Data!$R$2:$R$839,"Unique") -> 1184095 | F13: =IFERROR(E13/D13,0) -> 21.176568
